
Using Cuda
Traceback (most recent call last):
  File "main.py", line 48, in <module>
    outputs = model(inputs)
  File "/nfs/home/students/t.reim/.conda/envs/mamba2/lib/python3.8/site-packages/torch/nn/modules/module.py", line 1518, in _wrapped_call_impl
    return self._call_impl(*args, **kwargs)
  File "/nfs/home/students/t.reim/.conda/envs/mamba2/lib/python3.8/site-packages/torch/nn/modules/module.py", line 1527, in _call_impl
    return forward_call(*args, **kwargs)
  File "/nfs/home/students/t.reim/bachelor/pytorchtest/models/first_pytorch.py", line 45, in forward
    x1 = F.relu(self.fc1(x1))
  File "/nfs/home/students/t.reim/.conda/envs/mamba2/lib/python3.8/site-packages/torch/nn/modules/module.py", line 1518, in _wrapped_call_impl
    return self._call_impl(*args, **kwargs)
  File "/nfs/home/students/t.reim/.conda/envs/mamba2/lib/python3.8/site-packages/torch/nn/modules/module.py", line 1527, in _call_impl
    return forward_call(*args, **kwargs)
  File "/nfs/home/students/t.reim/.conda/envs/mamba2/lib/python3.8/site-packages/torch/nn/modules/linear.py", line 114, in forward
    return F.linear(input, self.weight, self.bias)
RuntimeError: Expected all tensors to be on the same device, but found at least two devices, cuda:0 and cpu! (when checking argument for argument mat1 in method wrapper_CUDA_addmm)